<?xml version="1.0" ?>
<robot xmlns:xacro="http://ros.org/wiki/xacro">
    <xacro:macro name="motoman_pl80" params="prefix">

    <!-- link list -->
    <link name="${prefix}base_link">
        <visual>
            <geometry>
                <mesh filename="package://motoman_pl80_support/meshes/visual/base_link.dae"/>
            </geometry>
        </visual>
        <collision>
            <geometry>
                <mesh filename="package://motoman_pl80_support/meshes/collision/base_link.stl"/>
            </geometry>
        </collision>
    </link>
    <link name="${prefix}link_1">
        <visual>
            <geometry>
                <mesh filename="package://motoman_pl80_support/meshes/visual/link_1.dae"/>
            </geometry>
        </visual>
        <collision>
            <geometry>
                <mesh filename="package://motoman_pl80_support/meshes/collision/link_1.stl"/>
            </geometry>
        </collision>
    </link>
    <link name="${prefix}link_2">
        <visual>
            <geometry>
                <mesh filename="package://motoman_pl80_support/meshes/visual/link_2.dae"/>
            </geometry>
        </visual>
        <collision>
            <geometry>
                <mesh filename="package://motoman_pl80_support/meshes/collision/link_2.stl"/>
            </geometry>
        </collision>
    </link>
    <link name="${prefix}link_3">
        <visual>
            <geometry>
                <mesh filename="package://motoman_pl80_support/meshes/visual/link_3.dae"/>
            </geometry>
        </visual>
        <collision>
            <geometry>
                <mesh filename="package://motoman_pl80_support/meshes/collision/link_3.stl"/>
            </geometry>
        </collision>
    </link>
    <link name="${prefix}link_4">
        <visual>
            <geometry>
                <mesh filename="package://motoman_pl80_support/meshes/visual/link_4.dae"/>
            </geometry>
        </visual>
        <collision>
            <geometry>
                <mesh filename="package://motoman_pl80_support/meshes/collision/link_4.stl"/>
            </geometry>
        </collision>
    </link>
    <link name="${prefix}link_5">
        <visual>
            <geometry>
                <mesh filename="package://motoman_pl80_support/meshes/visual/link_5.dae"/>
            </geometry>
        </visual>
        <collision>
            <geometry>
                <mesh filename="package://motoman_pl80_support/meshes/collision/link_5.stl"/>
            </geometry>
        </collision>
    </link>
    <!-- end of link list -->

    <!-- joint list -->
    <joint name="${prefix}joint_1" type="revolute">
        <parent link="${prefix}base_link"/>
        <child link="${prefix}link_1"/>
        <origin xyz="0 0 0.540" rpy="0 0 0" />
        <axis xyz="0 0 1" />
        <limit lower="${radians(-180)}" upper="${radians(180)}" effort="5516.24" velocity="${radians(180)}"/>
    </joint>
    <joint name="${prefix}joint_2" type="revolute">
        <parent link="${prefix}link_1"/>
        <child link="${prefix}link_2"/>
        <origin xyz="0.145 0 0" rpy="0 0 0" />
        <axis xyz="0 1 0" />
        <limit lower="${radians(-90)}" upper="${radians(135)}" effort="7060.79" velocity="${radians(180)}"/>
    </joint>
    <joint name="${prefix}joint_3" type="revolute">
        <parent link="${prefix}link_2"/>
        <child link="${prefix}link_3"/>
        <origin xyz="0 0 0.870" rpy="0 0 0" />
        <axis xyz="0 -1 0" />
        <limit lower="${radians(-80)}" upper="${radians(185)}" effort="3089.10" velocity="${radians(180)}"/>
    </joint>
    <joint name="${prefix}joint_4" type="revolute">
        <parent link="${prefix}link_3"/>
        <child link="${prefix}link_4"/>
        <origin xyz="1.025 0 0.210" rpy="0 0 0" />
        <axis xyz="0 -1 0" />
        <limit lower="${radians(-35)}" upper="${radians(175)}" effort="794.34" velocity="${radians(180)}"/>
    </joint>
    <joint name="${prefix}joint_5" type="revolute">
        <parent link="${prefix}link_4"/>
        <child link="${prefix}link_5"/>
        <origin xyz="0 0 0" rpy="0 0 0" />
        <axis xyz="0 0 1" />
        <limit lower="${radians(-360)}" upper="${radians(360)}" effort="375.10" velocity="${radians(500)}"/>
    </joint>
    <!-- end of joint list -->

    <!-- ROS base_link to Robot Manufacturer World Coordinates transform -->
    <link name="${prefix}base" />
    <joint name="${prefix}base_link-base" type="fixed">
        <origin xyz="0 0 0.540" rpy="0 0 0"/>
        <parent link="${prefix}base_link"/>
        <child link="${prefix}base"/>
    </joint>

    <!-- ROS-Industrial 'flange' frame, attachment point for EEF models -->
    <link name="${prefix}flange"/>
    <joint name="${prefix}joint_5-flange" type="fixed">
        <origin xyz="0 0 -0.175" rpy="0 ${radians(90)} 0"/>
        <parent link="${prefix}link_5"/>
        <child link="${prefix}flange"/>
    </joint>

    <!-- ROS-Industrial 'tool0' frame, all-zeros tool frame -->
    <link name="${prefix}tool0"/>
    <joint name="${prefix}flange-tool0" type="fixed">
        <origin xyz="0 0 0" rpy="0 ${radians(-90)} ${radians(180)}"/>
        <parent link="${prefix}flange"/>
        <child link="${prefix}tool0"/>
    </joint>

    </xacro:macro>
</robot>

