<?xml version="1.0" ?>
<robot xmlns:xacro="http://ros.org/wiki/xacro">
    <xacro:macro name="motoman_sia10f" params="prefix">
        <xacro:include filename="$(find motoman_resources)/urdf/common_materials.xacro"/>

        <!-- link list -->
        <link name="${prefix}base_link">
            <visual>
                <geometry>
                    <mesh filename="package://motoman_sia10f_support/meshes/sia10f/visual/base_link.stl" />
                </geometry>
                <xacro:material_yaskawa_blue/>
            </visual>
            <collision>
                <geometry>
                    <mesh filename="package://motoman_sia10f_support/meshes/sia10f/collision/base_link.stl" />
                </geometry>
                <material name="yellow">
                    <color rgba="0 1 1 1"/>
                </material>
            </collision>
        </link>
        <link name="${prefix}link_1_s">
            <visual>
                <geometry>
                    <mesh filename="package://motoman_sia10f_support/meshes/sia10f/visual/link_1.stl"/>
                </geometry>
                <xacro:material_yaskawa_white/>
            </visual>
            <collision>
                <geometry>
                    <mesh filename="package://motoman_sia10f_support/meshes/sia10f/collision/link_1.stl" />
                </geometry>
                <material name="yellow"/>
            </collision>
        </link>
        <link name="${prefix}link_2_l">
            <visual>
                <origin rpy="1.57 3.1416 0" xyz="0 0 0"/>
                <geometry>
                    <mesh filename="package://motoman_sia10f_support/meshes/sia10f/visual/link_2.stl"/>
                </geometry>
                <xacro:material_yaskawa_blue/>
            </visual>
            <collision>
                <origin rpy="1.57 3.1416 0" xyz="0 0 0"/>
                <geometry>
                    <mesh filename="package://motoman_sia10f_support/meshes/sia10f/collision/link_2.stl" />
                </geometry>
                <material name="yellow"/>
            </collision>
        </link>
        <link name="${prefix}link_3_e">
            <visual>
                <origin rpy="0 0 3.1415" xyz="0 0 0"/>
                <geometry>
                    <mesh filename="package://motoman_sia10f_support/meshes/sia10f/visual/link_3.stl"/>
                </geometry>
                <xacro:material_yaskawa_white/>
            </visual>
            <collision>
                <origin rpy="0 0 3.1415" xyz="0 0 0"/>
                <geometry>
                    <mesh filename="package://motoman_sia10f_support/meshes/sia10f/collision/link_3.stl" />
                </geometry>
                <material name="yellow"/>
            </collision>
        </link>
        <link name="${prefix}link_4_u">
            <visual>
                <origin rpy="1.57 -3.1415 0" xyz="0 0 0"/>
                <geometry>
                    <mesh filename="package://motoman_sia10f_support/meshes/sia10f/visual/link_4.stl"/>
                </geometry>
                <xacro:material_yaskawa_blue/>
            </visual>
            <collision>
                <origin rpy="1.57 -3.1415 0" xyz="0 0 0"/>
                <geometry>
                    <mesh filename="package://motoman_sia10f_support/meshes/sia10f/collision/link_4.stl" />
                </geometry>
                <material name="yellow"/>
            </collision>
        </link>
        <link name="${prefix}link_5_r">
            <visual>
                <origin rpy="0 0 3.1416" xyz="0 0 0"/>
                <geometry>
                    <mesh filename="package://motoman_sia10f_support/meshes/sia10f/visual/link_5.stl"/>
                </geometry>
                <xacro:material_yaskawa_white/>
            </visual>
            <collision>
                <origin rpy="0 0 3.1416" xyz="0 0 0"/>
                <geometry>
                    <mesh filename="package://motoman_sia10f_support/meshes/sia10f/collision/link_5.stl" />
                </geometry>
                <material name="yellow"/>
            </collision>
        </link>
        <link name="${prefix}link_6_b">
            <visual>
                <origin rpy="-1.57 0 3.1416" xyz="0 0 0"/>
                <geometry>
                    <mesh filename="package://motoman_sia10f_support/meshes/sia10f/visual/link_6.stl"/>
                </geometry>
                <xacro:material_yaskawa_blue/>
            </visual>
            <collision>
                <origin rpy="-1.57 0 3.1416" xyz="0 0 0"/>
                <geometry>
                    <mesh filename="package://motoman_sia10f_support/meshes/sia10f/collision/link_6.stl" />
                </geometry>
                <material name="yellow"/>
            </collision>
        </link>
        <link name="${prefix}link_7_t">
            <visual>
                <geometry>
                    <mesh filename="package://motoman_sia10f_support/meshes/sia10f/visual/link_7.stl" />
                </geometry>
                <xacro:material_yaskawa_white/>
            </visual>
            <collision>
                <geometry>
                    <mesh filename="package://motoman_sia10f_support/meshes/sia10f/collision/link_7.stl" />
                </geometry>
                <material name="yellow"/>
            </collision>
        </link>
        <!-- end of link list -->
        <!-- joint list -->
        <joint name="${prefix}joint_1_s" type="revolute">
            <parent link="${prefix}base_link"/>
            <child link="${prefix}link_1_s"/>
            <origin xyz="0 0 0.36" rpy="0 0 0"/>
            <axis xyz="0 0 1" />
            <limit lower="-3.1415" upper="3.1415" effort="0" velocity="2.9670" />
        </joint>
        <joint name="${prefix}joint_2_l" type="revolute">
            <parent link="${prefix}link_1_s"/>
            <child link="${prefix}link_2_l"/>
            <origin xyz="0 0 0" rpy="0 0 0"/>
            <axis xyz="0 1 0" />
            <limit lower="-1.9198" upper="1.9198" effort="0" velocity="2.9670" />
        </joint>
        <joint name="${prefix}joint_3_e" type="revolute">
            <parent link="${prefix}link_2_l"/>
            <child link="${prefix}link_3_e"/>
            <origin xyz="0 0 0.36" rpy="0 0 0"/>
            <axis xyz="0 0 1" />
            <limit lower="-2.9670" upper="2.9670" effort="0" velocity="2.9670" />
        </joint>
        <joint name="${prefix}joint_4_u" type="revolute">
            <parent link="${prefix}link_3_e"/>
            <child link="${prefix}link_4_u"/>
            <origin xyz="0 0 0" rpy="0 0 0"/>
            <axis xyz="0 -1 0" />
            <limit lower="-2.3561" upper="2.3561" effort="0" velocity="2.9670" />
        </joint>
        <joint name="${prefix}joint_5_r" type="revolute">
            <parent link="${prefix}link_4_u"/>
            <child link="${prefix}link_5_r"/>
            <origin xyz="0 0 0.360" rpy="0 0 0"/>
            <axis xyz="0 0 -1" />
            <limit lower="-3.1415" upper="3.1415" effort="0" velocity="3.4906" />
        </joint>
        <joint name="${prefix}joint_6_b" type="revolute">
            <parent link="${prefix}link_5_r"/>
            <child link="${prefix}link_6_b"/>
            <origin xyz="0 0 0" rpy="0 0 0"/>
            <axis xyz="0 -1 0" />
            <limit lower="-1.9198" upper="1.9198" effort="0" velocity="3.4906" />
        </joint>
        <joint name="${prefix}joint_7_t" type="revolute">
            <parent link="${prefix}link_6_b"/>
            <child link="${prefix}link_7_t"/>
            <origin xyz="0 0 0.155" rpy="0 0 0"/>
            <axis xyz="0 0 -1" />
            <limit lower="-3.1415" upper="3.1415" effort="0" velocity="6.9813" />
        </joint>
        <!-- end of joint list -->

        <!-- ROS base_link (via base_link) to Motoman Robot (not Base) Frame transform -->
        <link name="${prefix}base" />
        <joint name="${prefix}base_link-base" type="fixed">
            <origin xyz="0 0 0.360" rpy="0 0 0"/>
            <parent link="${prefix}base_link"/>
            <child link="${prefix}base"/>
        </joint>

        <!-- ROS-Industrial 'flange' frame: attachment point for EEF models -->
        <link name="${prefix}flange"/>
        <joint name="${prefix}joint_7_t-flange" type="fixed">
            <origin xyz="0 0 0" rpy="0 -1.57079632679 0"/>
            <parent link="${prefix}link_7_t"/>
            <child link="${prefix}flange"/>
        </joint>

        <!-- ROS-Industrial 'tool0' frame: all-zeros tool frame -->
        <link name="${prefix}tool0"/>
        <joint name="${prefix}flange-tool0" type="fixed">
            <origin xyz="0 0 0 " rpy="0 -1.57079632679 3.1415296"/>
            <parent link="${prefix}flange"/>
            <child link="${prefix}tool0"/>
        </joint>
        
    </xacro:macro>
</robot>
